<?xml version="1.0"?>
<robot xmlns:xacro="http://www.ros.org/wiki/xacro" name="inmoov">

  <!-- Supporting Feature Components -->
  <xacro:include filename="$(find inmoov_description)/urdf/config.joints.urdf.xacro" />
  <xacro:include filename="$(find inmoov_description)/urdf/config.inertial.urdf.xacro" />
  <xacro:include filename="$(find inmoov_description)/urdf/materials.urdf.xacro" />
  <xacro:include filename="$(find inmoov_description)/urdf/camera_sensor.urdf.xacro" />
  <!-- <xacro:include filename="$(find inmoov_description)/urdf/inmoov.transmission.urdf.xacro" /> -->

  <!-- These are the model components -->
  <xacro:include filename="$(find inmoov_description)/urdf/asmBase.urdf.xacro" />
  <xacro:include filename="$(find inmoov_description)/urdf/asmTorso.urdf.xacro" />
  <xacro:include filename="$(find inmoov_description)/urdf/asmHead.urdf.xacro" />
  <xacro:include filename="$(find inmoov_description)/urdf/asmEye.urdf.xacro" />
  <xacro:include filename="$(find inmoov_description)/urdf/asmFace.urdf.xacro" />
  <xacro:include filename="$(find inmoov_description)/urdf/asmArm.urdf.xacro" />
  <xacro:include filename="$(find inmoov_description)/urdf/asmHand.urdf.xacro" />

  
  <xacro:include filename="$(find inmoov_gazebo)/gazebo/inmoov.gazebo" />

  <property name="deg_to_rad" value="0.01745329251994329577"/>

  <link name="world"/>

  <joint name="fixed" type="fixed">
    <parent link="world"/>
    <child link="base_link"/>
  </joint>

  <link name="base_link">
    <visual>
      <geometry>
        <cylinder length="0.11" radius="0.26"/>
      </geometry> 
      <origin rpy="0 0 0" xyz="0 0 0.055"/>
      <xacro:base_color/>
    </visual>
  </link>

  <joint name="base_to_pedestal_link" type="fixed">
    <parent link="base_link"/>
    <child link="pedestal_link"/>
    <origin rpy="0 0 0"  xyz="0 0 0"/>
  </joint>

  <link name="pedestal_link">
    <visual>
      <geometry>
        <cylinder length="0.94" radius="0.0254"/>
      </geometry>
      <origin rpy="0 0 0" xyz="0 0 0.58"/>
      <xacro:base_color/>
    </visual>
  </link>



  <joint name="pedestal_to_mid_stomach_joint" type="fixed">
    <parent link="pedestal_link"/>
    <child link="mid_stomach_link"/>
    <origin rpy="0 0 0"  xyz="0 0 0"/>
  </joint>

  <xacro:torso covers="yes" />
  <!-- Jump to asmTorso.urdf.xacro to continue processing -->



  <!-- Don't know why but if I set bot head_tilt_link and head_roll_joint are set to revolute then the head flies off -->
  <joint name="head_roll_joint" type="fixed">
    <origin rpy="0 0 3.1415" xyz="-0.0315  -0.001 0.4551"/>
    <axis xyz="1 0 0"/>
    <limit effort="1000.0" lower="${head_roll_joint_lower}" upper="${head_roll_joint_upper}" velocity="${head_roll_joint_velocity}" />
    <parent link="torso_link"/>
    <child link="head_tilt_link"/>
  </joint>


  <link name="head_tilt_link">
    <visual>
      <geometry>
        <mesh filename="package://inmoov_description/meshes/virtual.stl" scale="0.001 0.001 0.001"/>
      </geometry>
      <origin rpy="0 0 3.1415" xyz="0 0 0"/>
      <xacro:frame_color/>
    </visual>
    <xacro:virtual_inertial/>
  </link>


  <joint name="head_tilt_joint" type="revolute">
    <axis xyz="0 1 0"/>
    <limit effort="1000.0" lower="${head_tilt_joint_lower}" upper="${head_tilt_joint_upper}" velocity="${head_tilt_joint_velocity}" />
    <origin rpy="0 0 3.1415" xyz="0 0 0"/>
    <parent link="head_tilt_link"/>
    <child link="head_base_link"/>
  </joint>

  <xacro:head covers="yes" />
<!-- Proceed to process asmHead.urdf.xacro -->



  <xacro:face covers="yes" />

  <joint name="face_joint" type="fixed">
    <origin rpy="0 0 0" xyz="0.0637 0 0.079"/>
    <parent link="skull_link"/>
    <child link="face_link"/>
  </joint>

  <xacro:arm side="r" flip="1" covers="yes" />




  <joint name="r_shoulder_out_joint" type="revolute">
    <axis xyz="1 0 0"/>
    <limit effort="1000.0" lower="${r_shoulder_out_joint_lower}" upper="${r_shoulder_out_joint_upper}" velocity="${r_shoulder_out_joint_velocity}" />
    <origin rpy="0 0 0" xyz="0 -0.143 0.298"/>
    <parent link="torso_link"/>
    <child link="r_shoulder_base_link"/>
  </joint>

  <transmission name="r_shoulder_out_joint_trans">
    <type>transmission_interface/SimpleTransmission</type>
    <joint name="r_shoulder_out_joint">
      <hardwareInterface>hardware_interface/PositionJointInterface</hardwareInterface>
    </joint>
    <actuator name="r_shoulder_out_joint_motor">
      <hardwareInterface>hardware_interface/PositionJointInterface</hardwareInterface>
      <mechanicalReduction>1</mechanicalReduction>
    </actuator>
  </transmission>

<!-- <xacro:transmission_block joint_name="l_shoulder_out_joint"/> -->

  <xacro:hand side="r" flip="1" covers="yes" />

  <joint name="r_wrist_roll_joint" type="revolute">
    <axis xyz="0 0 1"/>
    <limit effort="1000.0" lower="${r_wrist_roll_joint_lower}" upper="${r_wrist_roll_joint_upper}" velocity="${r_wrist_roll_joint_velocity}" />
    <origin rpy="0 0 0" xyz="-0.0144 0.01  -0.2885"/>
    <parent link="r_forearm_link"/>
    <child link="r_hand_link"/>
  </joint>

  <xacro:arm side="l" flip="-1" covers="yes" />

  <joint name="l_shoulder_out_joint" type="revolute">
    <axis xyz="1 0 0"/>
    <limit effort="1000.0" lower="${l_shoulder_out_joint_lower}" upper="${l_shoulder_out_joint_upper}" velocity="${l_shoulder_out_joint_velocity}" />
    <origin rpy="0 0 0" xyz="0 0.143 0.298"/>
    <parent link="torso_link"/>
    <child link="l_shoulder_base_link"/>
    <dynamics damping="50" friction="1"/>
  </joint>

  <transmission name="l_shoulder_out_joint_trans">
    <type>transmission_interface/SimpleTransmission</type>
    <joint name="l_shoulder_out_joint">
      <hardwareInterface>hardware_interface/PositionJointInterface</hardwareInterface>
    </joint>
    <actuator name="l_shoulder_out_joint_motor">
      <hardwareInterface>hardware_interface/PositionJointInterface</hardwareInterface>
      <mechanicalReduction>1</mechanicalReduction>
    </actuator>
  </transmission>



  <xacro:hand side="l" flip="-1" covers="yes" />

  <joint name="l_wrist_roll_joint" type="revolute">
    <axis xyz="0 0 1"/>
    <limit effort="1000.0" lower="${l_wrist_roll_joint_lower}" upper="${l_wrist_roll_joint_upper}" velocity="${l_wrist_roll_joint_velocity}" />
    <origin rpy="0 0 0" xyz="-0.0144 -0.01  -0.2885"/>
    <parent link="l_forearm_link"/>
    <child link="l_hand_link"/>
  </joint>


</robot>

