<?xml version="1.0"?>

<robot name="inmoov" xmlns:xacro="http://ros.org/wiki/xacro">

<xacro:include filename="$(find inmoov_description)/urdf/config.joints.urdf.xacro" />
<xacro:include filename="$(find inmoov_description)/urdf/config.inertial.urdf.xacro" />
<xacro:include filename="$(find inmoov_description)/urdf/materials.urdf.xacro" />
<xacro:include filename="$(find inmoov_description)/urdf/inmoov.gazebo" />

<!-- The following includes are for the various appendages -->
<xacro:include filename="$(find inmoov_description)/urdf/materials.urdf.xacro" />
<xacro:include filename="$(find inmoov_description)/urdf/asmBase.urdf.xacro" />
<xacro:include filename="$(find inmoov_description)/urdf/asmTorso.urdf.xacro" />
<xacro:include filename="$(find inmoov_description)/urdf/asmHead.urdf.xacro" />
<xacro:include filename="$(find inmoov_description)/urdf/asmEye.urdf.xacro" />
<xacro:include filename="$(find inmoov_description)/urdf/asmFace.urdf.xacro" />
<xacro:include filename="$(find inmoov_description)/urdf/asmArm.urdf.xacro" />
<xacro:include filename="$(find inmoov_description)/urdf/asmHand.urdf.xacro" />



<!-- For now we start with a world link.  This is because we have no legs yet -->
<!-- We are basically treating this as a stationary robot with a solid base -->
<!-- rather than a mobile robot.  A mobile robot will start with a "base_link" instead -->
<!-- The source I copied already has a base_link.  Maybe we start there later. -->
<!-- For now we will leave it as part of the robot and leave world as well  -->
<!-- We will change this later. -->
<!--  -->
  <link name="world"/>

  <joint name="fixed" type="fixed">
    <parent link="world"/>
    <child link="base_link"/>
  </joint>

  <link name="base_link">
    <inertial>
      <mass value="58.767261719000004"/>
      <inertia ixx="0.147272256" ixy="7.553278125e-05" ixz="0.055060208" iyy="0.134112088" iyz="-1.2159836913999999e-05" izz="0.156998304"/>
    </inertial>
    <collision>
      <origin rpy="0 0 0" xyz="0 0 0.055"/>
      <geometry>
        <cylinder length="0.11" radius="0.26"/>
      </geometry> 
    </collision>
    <visual>
      <geometry>
        <cylinder length="0.11" radius="0.26"/>
      </geometry> 
      <origin rpy="0 0 0" xyz="0 0 0.055"/>
      <xacro:base_color/>
    </visual>
  </link>

  <joint name="base_to_pedestal_link" type="fixed">
    <parent link="base_link"/>
    <child link="pedestal_link"/>
    <origin rpy="0 0 0"  xyz="0 0 0"/>
  </joint>

  <link name="pedestal_link">
    <collision>
      <origin xyz="0 0 0" rpy"0 0 0"/>
      <geometry>
        <cylinder length="0.11" radius="0.26"/>
      </geometry> 
    </collision>
    <visual>
      <geometry>
        <cylinder length="0.11" radius="0.26"/>
      </geometry> 
      <origin rpy="0 0 0" xyz="0 0 0.055"/>
      <xacro:base_color/>
    </visual>
    <inertial>
      <mass value="58.767261719000004"/>
      <inertia ixx="0.147272256" ixy="7.553278125e-05" ixz="0.055060208" iyy="0.134112088" iyz="-1.2159836913999999e-05" izz="0.156998304"/>
    </inertial>
  </link>

  <link name="head_tilt_link">
    <visual>
      <geometry>
        <mesh filename="package://inmoov_meshes/meshes/virtual.stl" scale="0.001 0.001 0.001"/>
      </geometry>
      <origin rpy="0 0 3.1415" xyz="0 0 0"/>
      <xacro:frame_color/>
    </visual>
    <xacro:virtual_inertial/>
  </link>

  <joint name="pedestal_to_mid_stomach_joint" type="fixed">
    <parent link="pedestal_link"/>
    <child link="mid_stomach_link"/>
     <origin rpy="0 0 0"  xyz="0 0 0"/>
  </joint>


  <!-- Run macro called "torso" in file asmTorso.urdf.xacro -->
  <xacro:torso covers="yes" />

  <joint name="head_roll_joint" type="revolute">
   <axis xyz="1 0 0"/>
   <limit effort="1000.0" lower="${head_roll_joint_lower}" upper="${head_roll_joint_upper}" velocity="${head_roll_joint_velocity}" />
   <origin rpy="0 0 3.1415" xyz="-0.0315  -0.001 0.4551"/>
   <parent link="torso_link"/>
   <child link="head_tilt_link"/>
  </joint>


  <joint name="head_tilt_joint" type="revolute">
   <axis xyz="0 1 0"/>
   <limit effort="1000.0" lower="${head_tilt_joint_lower}" upper="${head_tilt_joint_upper}" velocity="${head_tilt_joint_velocity}" />
   <origin rpy="0 0 3.1415" xyz="0 0 0"/>
   <parent link="head_tilt_link"/>
   <child link="head_base_link"/>
  </joint>

  
  <!-- Run macro called "head" in file asmHead.urdf.xacro -->
  <xacro:head covers="yes" />


  <!-- Run macro called "face" in file asmFace.urdf.xacro -->
  <xacro:face covers="yes" />

  <joint name="face_joint" type="fixed">
    <origin rpy="0 0 0" xyz="0.0637 0 0.079"/>
    <parent link="skull_link"/>
    <child link="face_link"/>
  </joint>


  <!-- Run macro called "face" in file asmArm.urdf.xacro -->
  <!-- We pass the param "side" in order to process 2 arms with 2 hands, right(r) in this case-->
  <xacro:arm side="r" flip="1" covers="yes" />

  <joint name="r_shoulder_out_joint" type="revolute">
   <axis xyz="1 0 0"/>
   <limit effort="1000.0" lower="${r_shoulder_out_joint_lower}" upper="${r_shoulder_out_joint_upper}" velocity="${r_shoulder_out_joint_velocity}" />
   <origin rpy="0 0 0" xyz="0 -0.143 0.298"/>
   <parent link="torso_link"/>
   <child link="r_shoulder_base_link"/>
  </joint>

  <xacro:hand side="r" flip="1" covers="yes" />

  <joint name="r_wrist_roll_joint" type="revolute">
   <axis xyz="0 0 1"/>
   <limit effort="1000.0" lower="${r_wrist_roll_joint_lower}" upper="${r_wrist_roll_joint_upper}" velocity="${r_wrist_roll_joint_velocity}" />
   <origin rpy="0 0 0" xyz="-0.0144 0.01  -0.2885"/>
   <parent link="r_forearm_link"/>
   <child link="r_hand_link"/>
  </joint>


  <xacro:arm side="l" flip="-1" covers="yes" />


  <!-- Run macro called "face" in file asmArm.urdf.xacro -->
  <!-- We pass the param "side" in order to process 2 arms with 2 hands, left(l) in this case-->
  <joint name="l_shoulder_out_joint" type="revolute">
   <axis xyz="1 0 0"/>
   <limit effort="1000.0" lower="${l_shoulder_out_joint_lower}" upper="${l_shoulder_out_joint_upper}" velocity="${l_shoulder_out_joint_velocity}" />
   <origin rpy="0 0 0" xyz="0 0.143 0.298"/>
   <parent link="torso_link"/>
   <child link="l_shoulder_base_link"/>
  </joint>

  <xacro:hand side="l" flip="-1" covers="yes" />

  <joint name="l_wrist_roll_joint" type="revolute">
   <axis xyz="0 0 1"/>
   <limit effort="1000.0" lower="${l_wrist_roll_joint_lower}" upper="${l_wrist_roll_joint_upper}" velocity="${l_wrist_roll_joint_velocity}" />
   <origin rpy="0 0 0" xyz="-0.0144 -0.01  -0.2885"/>
   <parent link="l_forearm_link"/>
   <child link="l_hand_link"/>
  </joint>

</robot>

